Workbook

Sheet Guiding Questions
A1: S/N | B1: Question | C1: Focus | D1: Goal
A2: 1 | B2: What are the most important outcomes you are responsible for? | C2: (Could limit to 2 or 3) | D2: This question seeks to help you both establish a clear and simple objective for the role.
A3: 2 | B3: What evidence is there to show that you have done a great Job? | C3: A simple answer indicating a positive change | D3: The aim here is to visualize what success looks like for the role. Additionally you would want to take note if the outcome can be quantified.
A4: 3 | B4: What activities or behaviours lead to these outcomes? | C4: Role and department specific. | D4: Aims to understand what drives success
A5: 4 | B5: Are they existing metrics or numbers that show success in these area? | D5: The goal is to understand how success is already measured.
A6: 5 | B6: If there are existing data, where does it come from? | C6: A system or report that generates or shows these data. | D6: This question points us to the data source. Verifying for data integrity.
A7: 6 | B7: What is the timeframe for measuring sucess? | C7: Semester, Monthly, weekly, Block, etc. | D7: This is to understand how often their work would yield results and what progress looks like within that timeframe.

Sheet Overview
B1: Operational Outcomes | E1: Student Outcomes
B2: Speed | C2: Quality | D2: Cost | E2: Student Autonomy | F2: Student Satisfaction | G2: Completion
A3: Definition | B3: Operations are executed with promptness in order to maximize efficiency and satisfaction. | C3: Operations are conducted at a high rate of quality, maximizing satisfaction. | D3: Operations reduce and control costs, allowing for efficiency and scalability of services. | E3: The proportion of students not needing help from the home office in order to navigate the student experience. | F3: Student levels of satisfaction with their services experience--coupled with autonomy, students are delighted with their service experience without needing help from the home office. | G3: The proportion of students retained and completing a credential.
A4: Examples | B4: Resolution rate Completion time Response time Processing time | C4: QA measures Accuracy Number of bugs or issues Process C-Sat 1st contact resolution Throughput rate Usage rate | D4: Wages Contractual services budget Compute costs Licenses ITD/ITS Costs per [unit of measure] | E4: What proportion of students submits an issue or process ticket for your services each term/year? | F4: Surveys or other forms of objective feedback indicating C-Sat with your specific services. Also consider other clients' satisfaction, as applicable. | G4: Application funnel Retention C1 Completion
B19: Question | C19: Goal | D19: Focus
B20: What are the most important operational outcomes this role is responsible for? | C20: This question seeks to help you both establish a clear objective for the role. | D20: As these are established, begin assigning them among the Operational and Student Outcomes
B21: How does this role impact the 3 imperitives of Student Services? (Autonomy, Satisfaction, Completion) | C21: Understanding this help guide which categories are most appropriate for setting KPIs.
B22: Does this role support the organization in providing critical services? | C22: If a role contributes to a critical services, it is important to ensure those things are measured by their KPIs. | D22: Critical services' are the services which every university must provide as a tertiary institution. Not every role does contribute to critical services, but if they do then it is good to have this in mind for setting KPIs.
B23: What evidence is there to show that you have done a great Job? | C23: The aim here is to visualize what success looks like for the role and identify what can be quantified.
B24: What activities or behaviours lead to these outcomes? | C24: Aims to understand what drives success | D24: Role and department specific.
B25: Are they existing metrics or numbers that show success in these area? | C25: The goal is to understand how success is already measured.
B26: If there are existing data, where does it come from? | C26: This question points us to the data source. Verifying for data integrity. | D26: A system or report that generates or shows these data.
B27: What is the timeframe for measuring sucess? | C27: This is to understand how often their work would yield results and what progress looks like within that timeframe. | D27: Semester, Monthly, weekly, Block, etc.

Sheet Dean of Students
A1: Employee Information | E1: Operational Outcomes | H1: Student Outcomes
A2: Employee Name | B2: Role | C2: Employment Status | D2: Stewardship | E2: Speed | F2: Quality | G2: Cost | H2: Student Autonomy | I2: Student Satisfaction | J2: Completion
A3: Steven K. Thomas | B3: Dean of Students | C3: FTE | D3: > Dean of Students office oversight > Title IX coordintor, ADA/Section 504 coordinator | F3: No material audit findings attributable to Dean of Students governance No legal findings attributable to Dean of Students governance No accreditation findings attributable to Dean of Students governance | G3: Annual DOS budget | I3: Overall student satisfaction (primary) | Y3: =_xlfn.TEXTJOIN(CHAR(10), TRUE, E3:G3) -> No material audit findings attributable to Dean of Students governance No legal findings attributable to Dean of Students governance No accreditation findings attributable to Dean of Students governance Annual DOS budget | Z3: =_xlfn.TEXTJOIN(CHAR(10), TRUE, H3:J3) -> Overall student satisfaction (primary)
A4: Anne Marie Clark | B4: Associate Dean of Students | C4: FTE | D4: > DOS operational lead > Deputy Title IX and ADA/Section 504 coordinator | E4: Dean of Students response time Dean of Students resolution time | F4: Dean of Students services escalation rates Partner C-Sat | Y4: =_xlfn.TEXTJOIN(CHAR(10), TRUE, E4:G4) -> Dean of Students response time Dean of Students resolution time Dean of Students services escalation rates Partner C-Sat | Z4: =_xlfn.TEXTJOIN(CHAR(10), TRUE, H4:J4)
A5: Katelyn Ray | B5: Student Honor & Conduct Coordinator | C5: FTE | D5: > CES Honor Code > Student conduct | E5: Honor and Conduct response time Honor and Conduct resolution time | F5: Rate of repeat offenders | Y5: =_xlfn.TEXTJOIN(CHAR(10), TRUE, E5:G5) -> Honor and Conduct response time Honor and Conduct resolution time Rate of repeat offenders | Z5: =_xlfn.TEXTJOIN(CHAR(10), TRUE, H5:J5)
A6: Ana De Castro | B6: Student Belonging Coordinator | C6: FTE | D6: > Non-Discrimination > Student belonging | F6: Discrimination resolution rate Student sentiment on belonging CSAT for Student Belonging | Y6: =_xlfn.TEXTJOIN(CHAR(10), TRUE, E6:G6) -> Discrimination resolution rate Student sentiment on belonging CSAT for Student Belonging | Z6: =_xlfn.TEXTJOIN(CHAR(10), TRUE, H6:J6)
A7: Sandra Wurttele | B7: Student Accessibility Coordinator | C7: Contractor | D7: > Deputy ADA/Section 504 coordinator | E7: Accommodation determination processing rate Accommodation resolution rate | F7: ADA and Section 504 standard compliance rate ADA and Section 504 Audit compliance rate | Y7: =_xlfn.TEXTJOIN(CHAR(10), TRUE, E7:G7) -> Accommodation determination processing rate Accommodation resolution rate ADA and Section 504 standard compliance rate ADA and Section 504 Audit compliance rate | Z7: =_xlfn.TEXTJOIN(CHAR(10), TRUE, H7:J7)
A8: Helen Reboucas | B8: Student Grievance Coordinator | C8: Contractor | D8: > Student grievances | E8: Student grievance case resolution time | F8: Grievance QA | Y8: =_xlfn.TEXTJOIN(CHAR(10), TRUE, E8:G8) -> Student grievance case resolution time Grievance QA | Z8: =_xlfn.TEXTJOIN(CHAR(10), TRUE, H8:J8)
A9: Joseph Bentum | B9: Student Crisis Coordinator | C9: Contractor | D9: > Students-in-Crisis > High-need case monitoring | E9: Crisis response time | Y9: =_xlfn.TEXTJOIN(CHAR(10), TRUE, E9:G9) -> Crisis response time | Z9: =_xlfn.TEXTJOIN(CHAR(10), TRUE, H9:J9)
Y10: =_xlfn.TEXTJOIN(CHAR(10), TRUE, D10:F10) | Z10: =_xlfn.TEXTJOIN(CHAR(10), TRUE, G10:I10)
Y11: =_xlfn.TEXTJOIN(" | ", TRUE, D11:F11) | Z11: =_xlfn.TEXTJOIN(" | ", TRUE, G11:I11)
Y12: =_xlfn.TEXTJOIN(" | ", TRUE, D12:F12) | Z12: =_xlfn.TEXTJOIN(" | ", TRUE, G12:I12)
Y13: =_xlfn.TEXTJOIN(" | ", TRUE, D13:F13) | Z13: =_xlfn.TEXTJOIN(" | ", TRUE, G13:I13)
Y14: =_xlfn.TEXTJOIN(" | ", TRUE, D14:F14) | Z14: =_xlfn.TEXTJOIN(" | ", TRUE, G14:I14)
Y15: =_xlfn.TEXTJOIN(" | ", TRUE, D15:F15) | Z15: =_xlfn.TEXTJOIN(" | ", TRUE, G15:I15)
Y16: =_xlfn.TEXTJOIN(" | ", TRUE, D16:F16) | Z16: =_xlfn.TEXTJOIN(" | ", TRUE, G16:I16)
Y17: =_xlfn.TEXTJOIN(" | ", TRUE, D17:F17) | Z17: =_xlfn.TEXTJOIN(" | ", TRUE, G17:I17)
Y18: =_xlfn.TEXTJOIN(" | ", TRUE, D18:F18) | Z18: =_xlfn.TEXTJOIN(" | ", TRUE, G18:I18)
Y19: =_xlfn.TEXTJOIN(" | ", TRUE, D19:F19) | Z19: =_xlfn.TEXTJOIN(" | ", TRUE, G19:I19)
Y20: =_xlfn.TEXTJOIN(" | ", TRUE, D20:F20) | Z20: =_xlfn.TEXTJOIN(" | ", TRUE, G20:I20)
Y21: =_xlfn.TEXTJOIN(" | ", TRUE, D21:F21) | Z21: =_xlfn.TEXTJOIN(" | ", TRUE, G21:I21)
Y22: =_xlfn.TEXTJOIN(" | ", TRUE, D22:F22) | Z22: =_xlfn.TEXTJOIN(" | ", TRUE, G22:I22)
... Y24: =_xlfn.TEXTJOIN(" | ", TRUE, D24:F24) | Z24: =_xlfn.TEXTJOIN(" | ", TRUE, G24:I24)

Sheet Digital Ops
A1: Employee Information | E1: Operational Outcomes | H1: Student Outcomes
A2: Employee Name | B2: Role | C2: Employment Status | D2: Stewardship | E2: Speed | F2: Quality | G2: Cost | H2: Student Autonomy | I2: Student Satisfaction | J2: Completion
A3: Jacob Adams | B3: Director of Digital Operations | C3: FTE | D3: > Digital operations oversight > Application and implementation of emerging technologies > Strategy for Power BI, machine learning, agentic AI, and Companion teams > UX evaluation & impact review | F3: Overall Stakeholder CSAT | G3: Digital Ops budget Costs saved by customers due to Digital Ops technologies (secondary) | H3: Overall student autonomy (secondary) | I3: Overall student satisfaction (secondary) | J3: Application Rate Retention Rate Completion Rate (Secondary) | Z3: =_xlfn.TEXTJOIN(CHAR(10), TRUE, E3:G3) -> Overall Stakeholder CSAT Digital Ops budget Costs saved by customers due to Digital Ops technologies (secondary) | AA3: =_xlfn.TEXTJOIN(CHAR(10), TRUE, H3:J3) -> Overall student autonomy (secondary) Overall student satisfaction (secondary) Application Rate Retention Rate Completion Rate (Secondary)
A4: Ricky Kailiponi Jr. | B4: Senior Manager of Digital Ops | C4: FTE | D4: > Business Partner collaboration > Architect & Engineer engagement (IT/ICS) > Development & QA lead > AI Compliance & advancement | E4: Team meeting project deadlines rate | F4: Companion feature C-Sat | H4: Companion usage rates | I4: Companion C-Sat | J4: AI retention effect | Z4: =_xlfn.TEXTJOIN(CHAR(10), TRUE, E4:G4) -> Team meeting project deadlines rate Companion feature C-Sat | AA4: =_xlfn.TEXTJOIN(CHAR(10), TRUE, H4:J4) -> Companion usage rates Companion C-Sat AI retention effect
A5: Joshua Stafford Hadden | B5: Operational Research & Reporting Manager | C5: FTE | D5: > Registrar business solutions > Operational data & reporting > SIS support & configuration | E5: Team meeting project timelines rate | F5: Stakeholder CSAT on team's projects | G5: Cost reductions in service areas (secondary) | Z5: =_xlfn.TEXTJOIN(CHAR(10), TRUE, E5:G5) -> Team meeting project timelines rate Stakeholder CSAT on team's projects Cost reductions in service areas (secondary) | AA5: =_xlfn.TEXTJOIN(CHAR(10), TRUE, H5:J5)
A6: David Peck | B6: Operational Data Analyst | C6: FTE | D6: > Power BI report management & refresh | E6: Project delivery on time rate | F6: Stakeholder CSAT - communication, quality of work, impact | Z6: =_xlfn.TEXTJOIN(CHAR(10), TRUE, E6:G6) -> Project delivery on time rate Stakeholder CSAT - communication, quality of work, impact | AA6: =_xlfn.TEXTJOIN(CHAR(10), TRUE, H6:J6)
A7: Pelenatita Neiufi | B7: Reporting & Evaluation Coordinator | C7: FTE | D7: > NSC & Enrollment reporting (BYUI & EC) > Student record updates (Demographics, SSN) > Qualitative research | E7: Project delivery on time rate | F7: Stakeholder CSAT - communication, quality of work, impact | Z7: =_xlfn.TEXTJOIN(CHAR(10), TRUE, E7:G7) -> Project delivery on time rate Stakeholder CSAT - communication, quality of work, impact | AA7: =_xlfn.TEXTJOIN(CHAR(10), TRUE, H7:J7)
A8: Victor Lamôni Calado Ferreira | B8: System & Operations Associate Registrar (title change) | C8: FTE | D8: > Registrar services for MLP students | E8: Project delivery on time rate | F8: Stakeholder CSAT - communication, quality of work, impact | Z8: =_xlfn.TEXTJOIN(CHAR(10), TRUE, E8:G8) -> Project delivery on time rate Stakeholder CSAT - communication, quality of work, impact | AA8: =_xlfn.TEXTJOIN(CHAR(10), TRUE, H8:J8)
A9: John Ayinde | B9: D365 & Automation Manager | C9: Contractor | D9: > Mentor Portal > Predictive Model Data Pipeline | E9: Stakeholder CSAT - timeliness per project | F9: Stakeholder CSAT - communication, quality of work, impact | Z9: =_xlfn.TEXTJOIN(CHAR(10), TRUE, E9:G9) -> Stakeholder CSAT - timeliness per project Stakeholder CSAT - communication, quality of work, impact | AA9: =_xlfn.TEXTJOIN(CHAR(10), TRUE, H9:J9)
A10: Samuel Riveros | B10: Companion & Special Projects Manager | C10: Contractor | D10: > Companion Front-End Stability & Usability > Companion–Analytics Engine Integration | E10: Stakeholder CSAT - timeliness per project | F10: Stakeholder CSAT - communication, quality of work, impact | Z10: =_xlfn.TEXTJOIN(CHAR(10), TRUE, E10:G10) -> Stakeholder CSAT - timeliness per project Stakeholder CSAT - communication, quality of work, impact | AA10: =_xlfn.TEXTJOIN(CHAR(10), TRUE, H10:J10)
A11: Aitana Toscano | B11: Data Manager | C11: Contractor | D11: > Power BI reporting lead > Backend Data stability & cleaning | E11: Stakeholder CSAT - timeliness per project | F11: Stakeholder CSAT - communication, quality of work, impact | Z11: =_xlfn.TEXTJOIN(CHAR(10), TRUE, E11:G11) -> Stakeholder CSAT - timeliness per project Stakeholder CSAT - communication, quality of work, impact | AA11: =_xlfn.TEXTJOIN(CHAR(10), TRUE, H11:J11)
A12: Isaias Zuñiga | B12: AI Manager | C12: Contractor | D12: > AI/ML Architecture development > Data Model development > Azure Board, GitHub, & DevOps Pipeline management | Z12: =_xlfn.TEXTJOIN(CHAR(10), TRUE, E12:G12) | AA12: =_xlfn.TEXTJOIN(CHAR(10), TRUE, H12:J12)
Z13: =_xlfn.TEXTJOIN(" | ", TRUE, E13:G13) | AA13: =_xlfn.TEXTJOIN(" | ", TRUE, H13:J13)
Z14: =_xlfn.TEXTJOIN(" | ", TRUE, E14:G14) | AA14: =_xlfn.TEXTJOIN(" | ", TRUE, H14:J14)
Z15: =_xlfn.TEXTJOIN(" | ", TRUE, E15:G15) | AA15: =_xlfn.TEXTJOIN(" | ", TRUE, H15:J15)
Z16: =_xlfn.TEXTJOIN(" | ", TRUE, E16:G16) | AA16: =_xlfn.TEXTJOIN(" | ", TRUE, H16:J16)
Z17: =_xlfn.TEXTJOIN(" | ", TRUE, E17:G17) | AA17: =_xlfn.TEXTJOIN(" | ", TRUE, H17:J17)
Z18: =_xlfn.TEXTJOIN(" | ", TRUE, E18:G18) | AA18: =_xlfn.TEXTJOIN(" | ", TRUE, H18:J18)
Z19: =_xlfn.TEXTJOIN(" | ", TRUE, E19:G19) | AA19: =_xlfn.TEXTJOIN(" | ", TRUE, H19:J19)
Z20: =_xlfn.TEXTJOIN(" | ", TRUE, E20:G20) | AA20: =_xlfn.TEXTJOIN(" | ", TRUE, H20:J20)
Z21: =_xlfn.TEXTJOIN(" | ", TRUE, E21:G21) | AA21: =_xlfn.TEXTJOIN(" | ", TRUE, H21:J21)
Z22: =_xlfn.TEXTJOIN(" | ", TRUE, E22:G22) | AA22: =_xlfn.TEXTJOIN(" | ", TRUE, H22:J22)
Z23: =_xlfn.TEXTJOIN(" | ", TRUE, E23:G23) | AA23: =_xlfn.TEXTJOIN(" | ", TRUE, H23:J23)
Z24: =_xlfn.TEXTJOIN(" | ", TRUE, E24:G24) | AA24: =_xlfn.TEXTJOIN(" | ", TRUE, H24:J24)
... Z42: =_xlfn.TEXTJOIN(" | ", TRUE, E42:G42) | AA42: =_xlfn.TEXTJOIN(" | ", TRUE, H42:J42)

Sheet Enrollment & Retention
A1: Employee Information | E1: Operational Outcomes | H1: Student Outcomes
A2: Employee Name | B2: Role | C2: Employment Status | D2: Stewardship | E2: Speed | F2: Quality | G2: Cost | H2: Student Autonomy | I2: Student Satisfaction | J2: Completion
A3: Alison Cundiff | B3: Director of Enrollment & Retention | C3: FTE | D3: > Enrollment services & mentoring oversight > Student retention and completion | G3: Enrollment & Retention budget | H3: Overall student autonomy (secondary) | I3: Overall student satisfaction (secondary) | J3: Enrollment, retention, completion (primary) | Z3: =_xlfn.TEXTJOIN(CHAR(10), TRUE, E3:G3) -> Enrollment & Retention budget | AA3: =_xlfn.TEXTJOIN(CHAR(10), TRUE, H3:J3) -> Overall student autonomy (secondary) Overall student satisfaction (secondary) Enrollment, retention, completion (primary)
A4: Katelyn Graf | B4: Senior Manager of Retention | C4: FTE | D4: > Retention performance and execution lead > Mentoring performance, strategy, and innovation | J4: PC Completion Rate First Certificate Completion Rate
A5: Kelley Richardson | B5: Mentoring Manager | C5: FTE | D5: > Mentoring program lead | E5: Mentor required action completion rate | F5: Mentor interaction QA | I5: Mentor CSAT | J5: Retention rate contribution by mentors | Z5: =_xlfn.TEXTJOIN(CHAR(10), TRUE, E5:G5) -> Mentor required action completion rate Mentor interaction QA | AA5: =_xlfn.TEXTJOIN(CHAR(10), TRUE, H5:J5) -> Mentor CSAT Retention rate contribution by mentors
A6: Mandy Schwab | B6: Mentoring Content Coordinator | C6: Full-Time Contractor | D6: > Mentoring program development | F6: Mentor interaction QA | I6: Mentor CSAT | Z6: =_xlfn.TEXTJOIN(CHAR(10), TRUE, E6:G6) -> Mentor interaction QA | AA6: =_xlfn.TEXTJOIN(CHAR(10), TRUE, H6:J6) -> Mentor CSAT
A7: Joanna Relkin | B7: Mentor Operations Coordinator | C7: Full-Time Contractor | D7: > Mentoring program operations | E7: Mentor required action completion rate | F7: Mentor concern case QA | Z7: =_xlfn.TEXTJOIN(CHAR(10), TRUE, E7:G7) -> Mentor required action completion rate Mentor concern case QA | AA7: =_xlfn.TEXTJOIN(CHAR(10), TRUE, H7:J7)
A8: Trevor Shelton | B8: Senior Manager of Enrollment Services | C8: FTE | D8: > Enrollment services lead > Enrollment funnel performance, strategy, and innovation | H8: Reduction of enrollment related support cases Reduction of admissions tier 2 support cases | J8: Application start to admission yield Admission to registration yield Registration to auto-drop yield | Z8: =_xlfn.TEXTJOIN(CHAR(10), TRUE, E8:G8) | AA8: =_xlfn.TEXTJOIN(CHAR(10), TRUE, H8:J8) -> Reduction of enrollment related support cases Reduction of admissions tier 2 support cases Application start to admission yield Admission to registration yield Registration to auto-drop yield
A9: Rachel Kirk | B9: Enrollment Counseling Manager | C9: FTE | D9: > Enrollment Counseling program lead | E9: Enrollment Counseling required action completion rate Enrollment Counseling contact rate by alert | F9: Enrollment Counseling CSAT rate Enrollment Counseling yield contribution | Z9: =_xlfn.TEXTJOIN(CHAR(10), TRUE, E9:G9) -> Enrollment Counseling required action completion rate Enrollment Counseling contact rate by alert Enrollment Counseling CSAT rate Enrollment Counseling yield contribution | AA9: =_xlfn.TEXTJOIN(CHAR(10), TRUE, H9:J9)
A10: Kimarie Howard | B10: Enrollment Counseling Development and Performance Coordinator | C10: Full-Time Contractor | D10: > Enrollment Counseling development and performance | F10: Enrollment Counseling CSAT rate Enrollment Counseling yield contribution | Z10: =_xlfn.TEXTJOIN(CHAR(10), TRUE, E10:G10) -> Enrollment Counseling CSAT rate Enrollment Counseling yield contribution | AA10: =_xlfn.TEXTJOIN(CHAR(10), TRUE, H10:J10)
A11: Megan Niblett | B11: Enrollment Counseling Operations Coordinator | C11: Full-Time Contractor | D11: > Enrollment Counseling operations | E11: Enrollment Counseling required action completion rate Enrollment Counseling contact rate by alert | Z11: =_xlfn.TEXTJOIN(CHAR(10), TRUE, E11:G11) -> Enrollment Counseling required action completion rate Enrollment Counseling contact rate by alert | AA11: =_xlfn.TEXTJOIN(CHAR(10), TRUE, H11:J11)
A12: Shaunasee Janette James | B12: Enrollment Coordinator | C12: FTE | D12: > Transfer evaluation > Ecclesiastical endorsement > Chaplain partnership | E12: Transfer evaluation processing rate Transfer evaluation case resolution rate | F12: Number of transfer evaluation cases | Z12: =_xlfn.TEXTJOIN(CHAR(10), TRUE, E12:G12) -> Transfer evaluation processing rate Transfer evaluation case resolution rate Number of transfer evaluation cases | AA12: =_xlfn.TEXTJOIN(CHAR(10), TRUE, H12:J12)
A13: Ely Zmolek | B13: Enrollment Services Specialist | C13: FTE | D13: > Application processing > Admissons exceptions > Admissions systems | E13: Application processing rate Application manual review turnaround rate | F13: Number of admissions support cases Admissions case resolution rate | Z13: =_xlfn.TEXTJOIN(CHAR(10), TRUE, E13:G13) -> Application processing rate Application manual review turnaround rate Number of admissions support cases Admissions case resolution rate | AA13: =_xlfn.TEXTJOIN(CHAR(10), TRUE, H13:J13)
B14: University Chaplain | C14: FTE | D14: > Ecclesiastical endorsements for non-member students | E14: Non-member endorsement completion rate | F14: Number of support cases with non-member endorsement concerns | Z14: =_xlfn.TEXTJOIN(CHAR(10), TRUE, E14:G14) -> Non-member endorsement completion rate Number of support cases with non-member endorsement concerns | AA14: =_xlfn.TEXTJOIN(CHAR(10), TRUE, H14:J14)
Z15: =_xlfn.TEXTJOIN(" | ", TRUE, E15:G15) | AA15: =_xlfn.TEXTJOIN(" | ", TRUE, H15:J15)
Z16: =_xlfn.TEXTJOIN(" | ", TRUE, E16:G16) | AA16: =_xlfn.TEXTJOIN(" | ", TRUE, H16:J16)
Z17: =_xlfn.TEXTJOIN(" | ", TRUE, E17:G17) | AA17: =_xlfn.TEXTJOIN(" | ", TRUE, H17:J17)
Z18: =_xlfn.TEXTJOIN(" | ", TRUE, E18:G18) | AA18: =_xlfn.TEXTJOIN(" | ", TRUE, H18:J18)
Z19: =_xlfn.TEXTJOIN(" | ", TRUE, E19:G19) | AA19: =_xlfn.TEXTJOIN(" | ", TRUE, H19:J19)
Z20: =_xlfn.TEXTJOIN(" | ", TRUE, E20:G20) | AA20: =_xlfn.TEXTJOIN(" | ", TRUE, H20:J20)
Z21: =_xlfn.TEXTJOIN(" | ", TRUE, E21:G21) | AA21: =_xlfn.TEXTJOIN(" | ", TRUE, H21:J21)
Z22: =_xlfn.TEXTJOIN(" | ", TRUE, E22:G22) | AA22: =_xlfn.TEXTJOIN(" | ", TRUE, H22:J22)
Z23: =_xlfn.TEXTJOIN(" | ", TRUE, E23:G23) | AA23: =_xlfn.TEXTJOIN(" | ", TRUE, H23:J23)
Z24: =_xlfn.TEXTJOIN(" | ", TRUE, E24:G24) | AA24: =_xlfn.TEXTJOIN(" | ", TRUE, H24:J24)
Z25: =_xlfn.TEXTJOIN(" | ", TRUE, E25:G25) | AA25: =_xlfn.TEXTJOIN(" | ", TRUE, H25:J25)
Z26: =_xlfn.TEXTJOIN(" | ", TRUE, E26:G26) | AA26: =_xlfn.TEXTJOIN(" | ", TRUE, H26:J26)
... Z32: =_xlfn.TEXTJOIN(" | ", TRUE, E32:G32) | AA32: =_xlfn.TEXTJOIN(" | ", TRUE, H32:J32)

Sheet Records, Registration, Supp (2)
A1: Employee Information | E1: Operational Outcomes | H1: Student Outcomes
A2: Employee Name | B2: Name | C2: Employment Status | D2: Stewardship | E2: Speed | F2: Quality | G2: Cost | H2: Student Autonomy | I2: Student Satisfaction | J2: Completion
A3: Mark Gefrom | B3: Director of Student Support | C3: FTE | D3: > Registrar, student support, Tech support oversight > Help center > Customer relations systems > Case systems | E3: Teams meeting or exceeding response service-level agreements Teams meeting or exceeding resolution service-level agreements | F3: Teams meeting QA service-level agreements Teams meeting CSAT service-level agreements Teams meeting first contact resolution service-level agreements | G3: Student records, registration, and support department budget | H3: Overall student autonomy (primary) | I3: Overall student satisfaction (secondary) | Z3: =_xlfn.TEXTJOIN(CHAR(10), TRUE, E3:G3) -> Teams meeting or exceeding response service-level agreements Teams meeting or exceeding resolution service-level agreements Teams meeting QA service-level agreements Teams meeting CSAT service-level agreements Teams meeting first contact resolution service-level agreements Student records, registration, and support department budget | AA3: =_xlfn.TEXTJOIN(CHAR(10), TRUE, H3:J3) -> Overall student autonomy (primary) Overall student satisfaction (secondary)
A4: Brad Lester | B4: Senior Manager of Student Support | C4: FTE | D4: > Inbound student support lead > Academic advising program | G4: Student support budget | H4: Autonomy rate for student support cases | Z4: =_xlfn.TEXTJOIN(CHAR(10), TRUE, E4:G4) -> Student support budget | AA4: =_xlfn.TEXTJOIN(CHAR(10), TRUE, H4:J4) -> Autonomy rate for student support cases
A5: Alyssa Burrell | B5: Student Support Coordinator | C5: FTE | D5: > Phone support > General support | E5: General support case response rate General support case resolution rate Phone answer speed Phone handle rate Agent availability | F5: Phone support QA Phone support CSAT Phone support first contact resolution | Z5: =_xlfn.TEXTJOIN(CHAR(10), TRUE, E5:G5) -> General support case response rate General support case resolution rate Phone answer speed Phone handle rate Agent availability Phone support QA Phone support CSAT Phone support first contact resolution | AA5: =_xlfn.TEXTJOIN(CHAR(10), TRUE, H5:J5)
A6: Hilary Bagley | B6: Training & Quality Assurance Manager | C6: FTE | D6: > Training, area collaboration, & partner communication > Media & Knowledge Base development > Student Support content accuracy > Student journey mapping | E6: Request-to-KB publish rate QA feedback cycle rate | F6: QA calibration consistency rate Knowledge Base audit pass rate QA team lead feedback success rate | G6: Cost per QA Evaluation ($ per Evaluation) Cost per KB Article Maintained ($ per Article Updated or Audited) | Z6: =_xlfn.TEXTJOIN(CHAR(10), TRUE, E6:G6) -> Request-to-KB publish rate QA feedback cycle rate QA calibration consistency rate Knowledge Base audit pass rate QA team lead feedback success rate Cost per QA Evaluation ($ per Evaluation) Cost per KB Article Maintained ($ per Article Updated or Audited) | AA6: =_xlfn.TEXTJOIN(CHAR(10), TRUE, H6:J6)
A7: Kira Hayes | B7: Training & Quality Assurance Coordinator | C7: FTE | D7: > caseing QA > External Knowledge Base articles > Support agent onboarding and training | E7: KB publishing rate | F7: QA evaluation completion rate DSAT and critical violation delivery rate | Z7: =_xlfn.TEXTJOIN(CHAR(10), TRUE, E7:G7) -> KB publishing rate QA evaluation completion rate DSAT and critical violation delivery rate | AA7: =_xlfn.TEXTJOIN(CHAR(10), TRUE, H7:J7)
A8: Matthew Smith | B8: Technical Support Manager | C8: FTE | D8: > Inbound tech support lead | E8: Tech support case resolution rate | G8: Tech support costs | H8: Autonomy rate for tech support cases | Z8: =_xlfn.TEXTJOIN(CHAR(10), TRUE, E8:G8) -> Tech support case resolution rate Tech support costs | AA8: =_xlfn.TEXTJOIN(CHAR(10), TRUE, H8:J8) -> Autonomy rate for tech support cases
A9: Colby Warner | B9: Product Support Engineer | C9: FTE | D9: > Tech support troubleshooting & resolution | E9: Escalated case resolution rate | F9: Tech Support case QA Tech Support case CSAT Tech Support case first contract resolution | Z9: =_xlfn.TEXTJOIN(CHAR(10), TRUE, E9:G9) -> Escalated case resolution rate Tech Support case QA Tech Support case CSAT Tech Support case first contract resolution | AA9: =_xlfn.TEXTJOIN(CHAR(10), TRUE, H9:J9)
A10: Kari Johnson | B10: Registrar | C10: FTE | D10: > Registration and Records lead > Academic record maintenance > Block/Term system and catalog data publishing | G10: Registrar budget | H10: Autonomy for registrar processes Autonomy for registrar cases | I10: Case CSAT for planning and registration | Z10: =_xlfn.TEXTJOIN(CHAR(10), TRUE, E10:G10) -> Registrar budget | AA10: =_xlfn.TEXTJOIN(CHAR(10), TRUE, H10:J10) -> Autonomy for registrar processes Autonomy for registrar cases Case CSAT for planning and registration
A11: Kim Overdiek | B11: Associate Registrar | C11: FTE | D11: > Policies & processes > Curriculum/catalog maintenance > Academic planning system configuration > Course registration process | E11: Process case resolution rate On-time catalog publishing rate On-time system configuration rate | F11: Process case QA Process case CSAT | Z11: =_xlfn.TEXTJOIN(CHAR(10), TRUE, E11:G11) -> Process case resolution rate On-time catalog publishing rate On-time system configuration rate Process case QA Process case CSAT | AA11: =_xlfn.TEXTJOIN(CHAR(10), TRUE, H11:J11)
A12: Tyson Bell | B12: Associate Registrar | C12: FTE | D12: > Student records >Transcripts >Graduation >Enrollment verification | E12: Records case resolution rate | F12: Records case QA Records case CSAT | Z12: =_xlfn.TEXTJOIN(CHAR(10), TRUE, E12:G12) -> Records case resolution rate Records case QA Records case CSAT | AA12: =_xlfn.TEXTJOIN(CHAR(10), TRUE, H12:J12)
A13: Angie Holt | B13: Graduation Coordinator | C13: Full-Time Contractor | D13: > Graduation application > Diploma awarding process | E13: Graduation application case completion rate Award processing rate | F13: Number of Rescinded Degrees Application QA Awarding QA | Z13: =_xlfn.TEXTJOIN(CHAR(10), TRUE, E13:G13) -> Graduation application case completion rate Award processing rate Number of Rescinded Degrees Application QA Awarding QA | AA13: =_xlfn.TEXTJOIN(CHAR(10), TRUE, H13:J13)
A14: Anne E. Owen | B14: Records & Transcript Coordinator | C14: FTE | D14: > Grade changes > Academic exceptions > Transcript requests | E14: Process case completion rate | F14: Process case CSAT Process case QA Transcript accuracy QA | Z14: =_xlfn.TEXTJOIN(CHAR(10), TRUE, E14:G14) -> Process case completion rate Process case CSAT Process case QA Transcript accuracy QA | AA14: =_xlfn.TEXTJOIN(CHAR(10), TRUE, H14:J14)
A15: Cindi C Putnam | B15: Planning Coordinator | C15: FTE | D15: > Degree progress audit corrections | E15: Degree planning escalation case resolution rate | F15: Degree planning escalation case CSAT Degree planning escalation case QA | Z15: =_xlfn.TEXTJOIN(CHAR(10), TRUE, E15:G15) -> Degree planning escalation case resolution rate Degree planning escalation case CSAT Degree planning escalation case QA | AA15: =_xlfn.TEXTJOIN(CHAR(10), TRUE, H15:J15)
A16: Nikki Jane Chambers | B16: Enrollment Verification Specialist | C16: FTT | D16: > Enrollment verification > Partner transfer evaluation > Apostilles > Student verification letters | E16: Enrollment verification completion rate Apostille completion rate | F16: Enrollment verification QA Apostille QA Enrollment verification CSAT Apostille C-Sat | Z16: =_xlfn.TEXTJOIN(CHAR(10), TRUE, E16:G16) -> Enrollment verification completion rate Apostille completion rate Enrollment verification QA Apostille QA Enrollment verification CSAT Apostille C-Sat | AA16: =_xlfn.TEXTJOIN(CHAR(10), TRUE, H16:J16)
A17: Daniel Zago | B17: Registration Specialist | C17: Contractor | D17: > Registration user testing > Registration support > Manual registration projects | E17: Registration issue case resolution rate | F17: Registration issue case QA Registration issue case CSAT | Z17: =_xlfn.TEXTJOIN(CHAR(10), TRUE, E17:G17) -> Registration issue case resolution rate Registration issue case QA Registration issue case CSAT | AA17: =_xlfn.TEXTJOIN(CHAR(10), TRUE, H17:J17)
Z18: =_xlfn.TEXTJOIN(" | ", TRUE, E18:J18)
Z19: =_xlfn.TEXTJOIN(" | ", TRUE, E19:J19)
Z20: =_xlfn.TEXTJOIN(" | ", TRUE, E20:J20)
Z21: =_xlfn.TEXTJOIN(" | ", TRUE, E21:J21)
Z22: =_xlfn.TEXTJOIN(" | ", TRUE, E22:J22)
Z23: =_xlfn.TEXTJOIN(" | ", TRUE, E23:J23)
Z24: =_xlfn.TEXTJOIN(" | ", TRUE, E24:J24)
Z25: =_xlfn.TEXTJOIN(" | ", TRUE, E25:J25)
Z26: =_xlfn.TEXTJOIN(" | ", TRUE, E26:J26)
Z27: =_xlfn.TEXTJOIN(" | ", TRUE, E27:J27)
Z28: =_xlfn.TEXTJOIN(" | ", TRUE, E28:J28)
Z29: =_xlfn.TEXTJOIN(" | ", TRUE, E29:J29)
Z30: =_xlfn.TEXTJOIN(" | ", TRUE, E30:J30)

Sheet Records, Registration, Support 
A1: Employee Information | E1: Operational Outcomes | H1: Student Outcomes
A2: Employee Name | B2: Name | C2: Employment Status | D2: Stewardship | E2: Speed | F2: Quality | G2: Cost | H2: Student Autonomy | I2: Student Satisfaction | J2: Completion
A3: Mark Gefrom | B3: Director of Student Support | C3: FTE | D3: > Registrar, student support, Tech support oversight > Help center > Customer relations systems > Case systems | E3: Teams meeting or exceeding response service-level agreements Teams meeting or exceeding resolution service-level agreements | F3: Teams meeting QA service-level agreements Teams meeting CSAT service-level agreements Teams meeting first contact resolution service-level agreements | G3: Student records, registration, and support department budget | H3: Overall student autonomy (primary) | I3: Overall student satisfaction (secondary) | Z3: =_xlfn.TEXTJOIN(CHAR(10), TRUE, E3:G3) -> Teams meeting or exceeding response service-level agreements Teams meeting or exceeding resolution service-level agreements Teams meeting QA service-level agreements Teams meeting CSAT service-level agreements Teams meeting first contact resolution service-level agreements Student records, registration, and support department budget | AA3: =_xlfn.TEXTJOIN(CHAR(10), TRUE, H3:J3) -> Overall student autonomy (primary) Overall student satisfaction (secondary)
A4: Brad Lester | B4: Senior Manager of Student Support | C4: FTE | D4: > Inbound student support lead > Academic advising program | E4: Student support case response rates Student support case resolution rates | F4: Student support QA Student support CSAT Student support first contact resolution | G4: Student support budget | H4: Autonomy rate for student support cases | Z4: =_xlfn.TEXTJOIN(CHAR(10), TRUE, E4:G4) -> Student support case response rates Student support case resolution rates Student support QA Student support CSAT Student support first contact resolution Student support budget | AA4: =_xlfn.TEXTJOIN(CHAR(10), TRUE, H4:J4) -> Autonomy rate for student support cases
A5: Alyssa Burrell | B5: Student Support Coordinator | C5: FTE | D5: > Phone support > General support | E5: General support case response rate General support case resolution rate Phone answer Speed Phone handle rate Agent availability | F5: Phone support QA Phone support CSAT Phone upport first contanct resolution | G5: Phone support costs | Z5: =_xlfn.TEXTJOIN(CHAR(10), TRUE, E5:G5) -> General support case response rate General support case resolution rate Phone answer Speed Phone handle rate Agent availability Phone support QA Phone support CSAT Phone upport first contanct resolution Phone support costs | AA5: =_xlfn.TEXTJOIN(CHAR(10), TRUE, H5:J5)
A6: Hilary Bagley | B6: Training & Quality Assurance Manager | C6: FTE | D6: > Training, area collaboration, & partner communication > Media & Knowledge Base development > Student Support content accuracy > Student journey mapping | E6: Request-to-KB publish rate QA feedback cycle rate | F6: QA calibration consistency rate Knowledge Base audit pass rate QA team lead feedback success rate | G6: Cost per QA Evaluation ($ per Evaluation) Cost per KB Article Maintained ($ per Article Updated or Audited) | Z6: =_xlfn.TEXTJOIN(CHAR(10), TRUE, E6:G6) -> Request-to-KB publish rate QA feedback cycle rate QA calibration consistency rate Knowledge Base audit pass rate QA team lead feedback success rate Cost per QA Evaluation ($ per Evaluation) Cost per KB Article Maintained ($ per Article Updated or Audited) | AA6: =_xlfn.TEXTJOIN(CHAR(10), TRUE, H6:J6)
A7: Kira Hayes | B7: Training & Quality Assurance Coordinator | C7: FTE | D7: > caseing QA > External Knowledge Base articles > Support agent onboarding and training | E7: KB publishing rate | F7: QA evaluation completion rate DSAT and critical violation delivery rate | G7: QA Team Costs Knowledge Base (KB) Team Costs | Z7: =_xlfn.TEXTJOIN(CHAR(10), TRUE, E7:G7) -> KB publishing rate QA evaluation completion rate DSAT and critical violation delivery rate QA Team Costs Knowledge Base (KB) Team Costs | AA7: =_xlfn.TEXTJOIN(CHAR(10), TRUE, H7:J7)
A8: Matthew Smith | B8: Technical Support Manager | C8: FTE | D8: > Inbound tech support lead | E8: Tech support case resolution rate | F8: Tech Support case QA Tech Support case CSAT Tech Support case first contract resolution | G8: Tech support costs | H8: Autonomy rate for tech support cases | Z8: =_xlfn.TEXTJOIN(CHAR(10), TRUE, E8:G8) -> Tech support case resolution rate Tech Support case QA Tech Support case CSAT Tech Support case first contract resolution Tech support costs | AA8: =_xlfn.TEXTJOIN(CHAR(10), TRUE, H8:J8) -> Autonomy rate for tech support cases
A9: Colby Warner | B9: Product Support Engineer | C9: FTE | D9: > Tech support troubleshooting & resolution | E9: Escalated case resolution rate Tech support case response rate | F9: Tech Support case QA Tech Support case CSAT Tech Support case first contract resolution | Z9: =_xlfn.TEXTJOIN(CHAR(10), TRUE, E9:G9) -> Escalated case resolution rate Tech support case response rate Tech Support case QA Tech Support case CSAT Tech Support case first contract resolution | AA9: =_xlfn.TEXTJOIN(CHAR(10), TRUE, H9:J9)
A10: Kari Johnson | B10: Registrar | C10: FTE | D10: > Registration and Records lead > Academic record maintenance > Block/Term system and catalog data publishing | E10: Registrar process resolution rate Registrar case resolution rate | F10: CSAT for registrar processes CSAT for registrar cases | G10: Registrar budget | H10: Autonomy for registrar processes Autonomy for registrar cases | I10: Case C-Sat for planning and registration | Z10: =_xlfn.TEXTJOIN(CHAR(10), TRUE, E10:G10) -> Registrar process resolution rate Registrar case resolution rate CSAT for registrar processes CSAT for registrar cases Registrar budget | AA10: =_xlfn.TEXTJOIN(CHAR(10), TRUE, H10:J10) -> Autonomy for registrar processes Autonomy for registrar cases Case C-Sat for planning and registration
A11: Kim Overdiek | B11: Associate Registrar | C11: FTE | D11: > Policies & processes > Curriculum/catalog maintenance > Academic planning system configuration > Course registration process | E11: Process case resolution rate On-time catalog publishing rate On-time system configuration rate | F11: Process case QA Process case CSAT Score | G11: Planning and registration team costs | Z11: =_xlfn.TEXTJOIN(CHAR(10), TRUE, E11:G11) -> Process case resolution rate On-time catalog publishing rate On-time system configuration rate Process case QA Process case CSAT Score Planning and registration team costs | AA11: =_xlfn.TEXTJOIN(CHAR(10), TRUE, H11:J11)
A12: Tyson Bell | B12: Associate Registrar | C12: FTE | D12: > Student records >Transcripts >Graduation >Enrollment verification | E12: Records case resolution rate | F12: Records case QA Records case CSAT | G12: Records team costs | Z12: =_xlfn.TEXTJOIN(CHAR(10), TRUE, E12:G12) -> Records case resolution rate Records case QA Records case CSAT Records team costs | AA12: =_xlfn.TEXTJOIN(CHAR(10), TRUE, H12:J12)
A13: Geraldine Susan Bean | B13: Graduation Coordinator | C13: FTE | D13: > Graduation application > Diploma awarding process | E13: Graduation application case completion rate Award processing rate | F13: Number of Rescinded Degrees Application QA Awarding QA | G13: Graduation team costs | Z13: =_xlfn.TEXTJOIN(CHAR(10), TRUE, E13:G13) -> Graduation application case completion rate Award processing rate Number of Rescinded Degrees Application QA Awarding QA Graduation team costs | AA13: =_xlfn.TEXTJOIN(CHAR(10), TRUE, H13:J13)
A14: Anne E. Owen | B14: Records & Transcript Coordinator | C14: FTE | D14: > Grade changes > Academic exceptions > Transcript requests | E14: Process case completion rate | F14: Process case CSAT Process case QA Transcript Accuracy QA | G14: Process team costs | Z14: =_xlfn.TEXTJOIN(CHAR(10), TRUE, E14:G14) -> Process case completion rate Process case CSAT Process case QA Transcript Accuracy QA Process team costs | AA14: =_xlfn.TEXTJOIN(CHAR(10), TRUE, H14:J14)
A15: Cindi C Putnam | B15: Planning Coordinator | C15: FTE | D15: > Degree progress audit corrections | E15: Degree planning escalation case resolution rate | F15: Degree Planning Escalation case CSAT Score Degree Planning Escalation case QA Score | G15: Degree planning team costs | Z15: =_xlfn.TEXTJOIN(CHAR(10), TRUE, E15:G15) -> Degree planning escalation case resolution rate Degree Planning Escalation case CSAT Score Degree Planning Escalation case QA Score Degree planning team costs | AA15: =_xlfn.TEXTJOIN(CHAR(10), TRUE, H15:J15)
A16: Nikki Jane Chambers | B16: Enrollment Verification Specialist | C16: FTT | D16: > Enrollment verification > Partner transfer evaluation > Apostilles > Student verification letters | E16: Enrollment verification completion rate Apostille completion rate | F16: Enrollment verification QA Apostille QA Enrollment verification CSAT Apostille C-Sat | G16: Enrollment verification team costs | Z16: =_xlfn.TEXTJOIN(CHAR(10), TRUE, E16:G16) -> Enrollment verification completion rate Apostille completion rate Enrollment verification QA Apostille QA Enrollment verification CSAT Apostille C-Sat Enrollment verification team costs | AA16: =_xlfn.TEXTJOIN(CHAR(10), TRUE, H16:J16)
A17: Angie Holt | B17: Registration Specialist | C17: Contractor | D17: > Registration user testing > Registration support > Manual registration projects | E17: Registration issue case resolution rate | F17: Registration issue case QA Registration issue case CSAT | G17: Registration team costs | Z17: =_xlfn.TEXTJOIN(CHAR(10), TRUE, E17:G17) -> Registration issue case resolution rate Registration issue case QA Registration issue case CSAT Registration team costs | AA17: =_xlfn.TEXTJOIN(CHAR(10), TRUE, H17:J17)
Z18: =_xlfn.TEXTJOIN(" | ", TRUE, E18:J18)
Z19: =_xlfn.TEXTJOIN(" | ", TRUE, E19:J19)
Z20: =_xlfn.TEXTJOIN(" | ", TRUE, E20:J20)
Z21: =_xlfn.TEXTJOIN(" | ", TRUE, E21:J21)
Z22: =_xlfn.TEXTJOIN(" | ", TRUE, E22:J22)
Z23: =_xlfn.TEXTJOIN(" | ", TRUE, E23:J23)
Z24: =_xlfn.TEXTJOIN(" | ", TRUE, E24:J24)
Z25: =_xlfn.TEXTJOIN(" | ", TRUE, E25:J25)
Z26: =_xlfn.TEXTJOIN(" | ", TRUE, E26:J26)
Z27: =_xlfn.TEXTJOIN(" | ", TRUE, E27:J27)
Z28: =_xlfn.TEXTJOIN(" | ", TRUE, E28:J28)
Z29: =_xlfn.TEXTJOIN(" | ", TRUE, E29:J29)
Z30: =_xlfn.TEXTJOIN(" | ", TRUE, E30:J30)

Sheet 2025 Baseline KPIs
A1: Employee Name | B1: Role | C1: Department | D1: Scheduling | E1: Key Responsibilities | F1: Current Projects (If Any) | G1: Conditions for Success | H1: Current KPIs | I1: Suggested KPIs | J1: Data Source | K1: Timeframe | L1: Ben's Thought
A2: Steven K. Thomas | B2: Dean of Students | C2: DOS | D2: Complete | E2: > Provide executive-level and strategic leadership for all six DOS Office service areas (Student Honor & Conduct; Accessibility; Belonging; Grievances; Sexual Misconduct/Title IX; Students in Crisis). > Title IX Coordinator and ADA/Sec. 504 Coordinator for the institution. > Set vision, strategic direction, and institutional alignment for the DOS Office across BYU-Pathway Worldwide’s global student body. > Lead policy development, cross-institutional coordination, and executive-level stakeholder collaboration (BYU-Idaho, Ensign College, ICS/IT, GEO, Digital Ops, etc.). > Oversee crisis-response strategy, including escalation frameworks, global monitoring, partner communication pathways, and institutional student-safety protocols. > Direct development and implementation of DOS Office reporting dashboards, analytics tools, and annual reports. > Steward DOS Office staffing, operational budget, contractor strategy, and technological modernization initiatives. > Represent the DOS Office in executive councils, SSEC, cross-institutional committees, accreditation-related efforts, and Student Success imperatives. | F2: > Student Crisis Portfolio development > Multi-Language Program (MLP) DOS Office implementation roadmap > DOS Partner Resource Portal (policies, workflows, referral processes) > DOS Office Annual Report design and launch (impact, case data, findings, predictive insights) > Technological innovation initiatives supported by ITD funding > Companion App feature expansion across all six services areas (Accessibility workflows, case intake, etc.). > Executive Secretary/Project Manager onboarding and integration > Data standardization with Digital Ops (DOS Office Power BI Dashboard) | G2: > DOS Office processes standardized globally with clear escalation pathways > Accurate, timely DOS Office dashboards for all six service areas > Strong cross-institutional alignment with partner schools and internal departments > Student trust and case-resolution consistency across regions > Effective utilization of Digital Ops, Springboard teams, and contractor talent > Documented, scalable procedures usable at 190+ country scale | H2: > Successful decoupling from partner institutions across all six DOS Office service areas. | I2: High-Level Strategic / Executive Focus 1. Operational Clarity & Scalability • Complete DOS Office Position Descriptions, Success Measures, and full process documentation across all six service areas. • Finalize succession plans for critical roles. • Validate and deliver scalability plans to support future growth to 1 million students. 2. Stakeholder & Student Satisfaction • Implement quarterly CSAT surveys for internal and external partners. • Launch post-interaction student CSAT surveys across service areas and integrate results into dashboards. • Demonstrate measurable increases in partner trust and clarity with DOS processes. 3. Cross-Institutional Collaboration & Alignment • Ensure DOS-chaired committees produce documented outcomes and alignment with partner institutions. • Strengthen year-round collaboration and communication with institutional partners. • Improve system health and reduce friction across shared processes. 4. High-Quality, Scalable Performance • Achieve student satisfaction with DOS services at or above 80%. • Resolve 90%+ of DOS tickets within 5 days (excluding Title IX/Sexual Misconduct timelines). • Demonstrate dashboard readiness and data accuracy for all service areas. 5. Retention & Completion Impact • Establish realistic retention and completion benchmarks for students who receive DOS Office services. | J2: > Power BI dashboards (DOS service areas) > Adobe Analytics (student behavior and case-flow insights) > Digital Ops data pipelines > Crisis monitoring systems and global intelligence feeds > Companion App and REACH/CRM case records | K2: Ongoing – Block, Quarterly, and Annual Reporting Cycles
A3: Anne Marie Clark | B3: Associate Dean of Students | C3: DOS | D3: Complete | E3: > Provide operational leadership and oversight for DOS Office teams and service areas. > Deputy Title IX Coordinator and Duputy ADA/Sec. 504 Coordinator for the institution. > Lead day-to-day coordination of policies, case management practices, instructor support workflows, and DOS Office procedural alignment. > Ensure consistency and accuracy in case handling, documentation, student communication, and compliance across all six service areas. > Oversee cross-departmental coordination with Enrollment Counseling, Mentoring, Support & Services, and Digital Ops. > Support implementation of DOS dashboards, data-cleaning initiatives, and service-area reporting. > Manage sensitive and escalated student cases; provide counsel to internal partners and managers. > Lead workforce training for policies, referral workflows, and crisis-scenario readiness. > Support development of the DOS Partner Resource Portal and Annual DOS Office Report. | F3: > DOS Office case-practice standardization and documentation > Internal and partner-facing student crisis-response guidance and escalation pathways > DOS dashboards data-accuracy initiative with Digital Ops > Policies and workflow alignment for internal staff and partner instituitions > Support & Services escalation improvement initiative > Annual DOS Office Report (data, narrative, outcomes) | G3: > Clean, reliable, and consistently entered DOS Office data > Clear and documented processes for internal staff and external partners > Strengthened relationships with partner schools and internal stakeholders > Reduced student touchpoints and faster resolution timelines > Improved operational accuracy and consistency across case managers and coordinators | H3: > Efficient and effective case resolution across all six DOS Office service areas. | I3: Operational / Execution Focus 1. Process Fidelity & Documentation • Maintain service-area Standard Operational Procedures (SOPs), escalation guides, and workflow documentation. • Achieve 100% implementation of updated processes within established timelines. 2. Case Quality & Consistency • Maintain 90%+ accuracy in case documentation and data entry. • Reduce procedural errors and repeat student contacts. • Ensure consistent adherence to policy and procedural standards. 3. Ticket Resolution & Service Performance • Resolve 85–90% of tickets within defined timelines (within 5 days for non-Title IX cases). • Reduce Support & Services delays impacting DOS cases. 4. Dashboard & Data Reliability • Conduct weekly data-quality verification (accuracy, completeness, consistency). • Meet dashboard-readiness milestones in partnership with Digital Ops. 5. Stakeholder Communication & Alignment • Maintain positive feedback from Instructors, GEO, Communications, and partner institutions. • Deliver quarterly updates to partner institutions and cross-departmental teams on schedule. 6. Training & Readiness • Ensure 100% of instructors, mentors, internal staff, and partners are trained in revised escalation and crisis-response processes. • Improve partner understanding of DOS procedures as reflected in CSAT and quarterly reviews. 7. Student & Partner Satisfaction Implementation • Execute student and partner CSAT survey distribution. • Monitor response trends and apply insights into operational improvements. | J3: > Power BI dashboards (DOS service areas) > Adobe Analytics (student behavior and case-flow insights) > Digital Ops data pipelines > Crisis monitoring systems and global intelligence feeds > Companion App and REACH/CRM case records | K3: Ongoing – Block, Quarterly, and Annual Reporting Cycles
A4: Katelyn Ray | B4: Student Honor & Grievance Coordinator | C4: DOS | D4: Complete | E4: > Place Holds on Student Accounts > Scheduled Phone calls with Disgruntled students > Grievances weekly team meeting > Enroll students in Academic Integrity Course > Coordination with BYU-I & Ensign Honor Offices > DOS weekly team meeting > Compile data regarding trends for grievances for past week/month > Manage the Navigating Academic Honesty course on Canvas | F4: Student honor and conduct committee Co-chair Adding AI section to Navigating Academic Honesty course on Canvas | G4: Tracks student honor violations and ensures that appropriate action is taken in each case to resolve the concern in accordance with our institution policies. Ensure a strong relationship with BYU-I & Ensign Honor Offices Maintain open communication and strong relationship with instructional teams to streamline violation processing. | H4: Number of cases received - tracked Number of repeat offender - tracked Case age, 5 days or less - 90% | I4: CSAT - Students | J4: > Power BI dashboards (DOS service areas) > Adobe Analytics (student behavior and case-flow insights) > Digital Ops data pipelines > Crisis monitoring systems and global intelligence feeds > Companion App and REACH/CRM case records | K4: Weekly
A5: Alison Cundiff | B5: Director of Enrollment & Retention | C5: Enrollment & Retention | D5: Pending - Extended to Friday Dec 5th | E5: > Oversee the Enrollment Counselling and Mentoring teams: >> 1:1s >> Team meetings >> Long-Term planning to meet Student Success and Organizational objectives > Oversee student throughput across the student journey/pipeline >> Milestones >> Dashboards >> AI/Human intervention strategies > Report on progress in weekly 1:1 with the VP of Student Success. > Represent EC and Mentoring in daily, weekly, and monthly cross-functional meetings related to registration. > Prepare agendas and facilitate the Retention Council, various workgroup participation | F5: Retention Council (Chair) Orientation, Analytics Engine Workgroup (Chair) Enrollment & Retention Suite dashboard project w/ Dallin Milestone map project EC3 Mentor exploration CARE Committee (participant) CES Student Success Committee (participant) Companion Implementation Taskforce (participant) Advising Committee (participant) | G5: Mentoring is functioning optimally, mentor role is clear, and students know how to reach their mentor. Enrollment Counseling is functioning optimally, and that we have the right intervention model set up to increase yield rates from Application to Registration. Teams have all the resources (access to data, systems) needed to perform their roles in a paced and effective way. We are aligned across the organization on the primary persistence and retention measurements and are consistently making progress on them from term to term, year to year. | H5: EC RA completion 95% average Mentor CSAT - 85% average Mentor RA Implementation - 90% completion Mentor Scorecard (Quality) - 85% average PC Completion: 45% C&D 4-Term Retention: 55% C1 Completion: 40% | I5: None | J5: > https://app.fabric.microsoft.com/groups/4f9c84ba-b5d3-4eda-a86b-41fbb3b3bc4a/reports/d0f58bce-3a7d-49b6-80a3-eade14ab09fc/e3ff97a21eaacb03dbca?experience=fabric-developer&clientSideAuth=0 > https://app.powerbi.com/groups/me/reports/7177fab9-23b0-4184-8f31-f0db822282c0/ReportSection964c860de430a5035bab?ctid=61e6eeb3-5fd7-4aaa-ae3c-61e8deb09b79&experience=power-bi > https://app.powerbi.com/groups/4f9c84ba-b5d3-4eda-a86b-41fbb3b3bc4a/reports/8b8c6aa8-361e-4ed7-8018-ac9b625ec004/51439a40d9bbc658cac9?experience=power-bi > https://app.powerbi.com/groups/4f9c84ba-b5d3-4eda-a86b-41fbb3b3bc4a/reports/e2b5b9d8-0b16-4185-9213-61b41d61c157/40663d76a0ae8a192407?experience=power-bi | K5: Weekly, Monthly, and By Term
A6: Rachel Kirk | B6: Enrollment Counseling Manager | C6: Enrollment & Retention | D6: Complete | E6: > Supporting my team and escalating complicated issues (50%) > Cross-departmental collaboration (15%) > Planning targeted outreach (10%) > Monitoring enrollment counseling effectiveness/performance (10%) > Planning and Requesting optimization to our tools (5%) > Synthesize and present results of key initiatives and team performance to senior leadership (10%) | F6: New Student Orientation Workgroup | G6: Ensuring that the EC team is functioning effectively and supporting students Planning RAs and outreach Tracking tool efficacy and ensuring tool repair and updates | H6: RA completion 95% average | I6: EC CSAT 85% average - New metric being tracked | J6: > https://app.fabric.microsoft.com/groups/4f9c84ba-b5d3-4eda-a86b-41fbb3b3bc4a/reports/d0f58bce-3a7d-49b6-80a3-eade14ab09fc/e3ff97a21eaacb03dbca?experience=fabric-developer&clientSideAuth=0 > https://app.powerbi.com/groups/me/reports/7177fab9-23b0-4184-8f31-f0db822282c0/ReportSection964c860de430a5035bab?ctid=61e6eeb3-5fd7-4aaa-ae3c-61e8deb09b79&experience=power-bi | K6: Weekly
A7: Kelley Richardson | B7: Mentoring Manager | C7: Enrollment & Retention | D7: Complete | E7: > Implement the Mentoring Strategy > CRM needs and adjustments > Oversee Mentor & Evaluator training sessions > Supply guides and Required Action Implementation to standardize and inform Mentors regarding changes made and process updates. > Build and maintain the mentor scorecard model. > Implement and quality assure items in Mentoring such as Case Management and Mentor Interaction with students (timing, frequency, and quality). | F7: MLP Portuguese Pilot mentors EC3 Project Pilot mentor update | G7: Mentoring strategy is being implemented successfully. Mentors & Evaluators trainings are provided to Springboard before new items are expected to be implemented. Mentor guides & RA guides are provided and updated as needed. Mentor Evaluation updates are delivered regularly | H7: Mentor CSAT - 85% average RA Implementation - 90% completion Scorecard (Quality) - 85% average | I7: None | J7: https://app.powerbi.com/groups/4f9c84ba-b5d3-4eda-a86b-41fbb3b3bc4a/reports/8b8c6aa8-361e-4ed7-8018-ac9b625ec004/51439a40d9bbc658cac9?experience=power-bi https://app.powerbi.com/groups/4f9c84ba-b5d3-4eda-a86b-41fbb3b3bc4a/reports/e2b5b9d8-0b16-4185-9213-61b41d61c157/40663d76a0ae8a192407?experience=power-bi | K7: Weekly & by Term
A8: Jacob Adams | B8: Director of Digital Operations | C8: Digital Ops | D8: Complete | E8: > Strategic discernment of analytics engine (backend) and Companion/Mentor portal (frontend) feature alignment, development, and maintenance to scale to millions of students in multiple languages with the best of AI and human relationship-based intervention. > Daily/weekly scrum meetings with human role applications on behalf of students aligned with analytics engine with Companion, PowerBI, and machine learning and agentic AI teams. > Review non-linear and linear UX impacts and results. | F8: None | G8: Digital Ops projects are progressing on time and completed project meet their requirements. Stakeholder approval with high satisfaction. | H8: None | I8: 85% CSAT in Companion 100% uptime (0% P1s) with clear pro-active maintenance windows communicated to students and stakeholders Each prompt/answer in Companion 98% QA accurate/relevant/ethical/accountable separated by feature (i.e. jobs, course assistant, Versant prep assistant, etc.) Simulate results for stability in Azure with 1 million students in Spanish, Portuguese, French, English (i.e. 98% accuracy, 100% uptime, 3% milestone achievement over predicted) Predictive model accuracy 92% on average for each micro-milestone | J8: PowerBI Azure chat transcript tables Microsoft Application Insights Azure notebooks | K8: > CSAT and Uptime - daily > QA weekly
A9: Ricky Kailiponi Jr. | B9: Senior Manager of Digital Ops | C9: Digital Ops | D9: Complete | E9: > Collaborate with IT and ICS partners, including solution managers Kyle C. and Jeff Van Drimmelen, product managers Dustin Waith (Registration), Cary Johnson (formerly EC3), Johanna Powell (Admissions), Mike Hilmo (Finance/Gatherings), and Chad Neth (Reach), and ICS developers Bob Capel and Gordon Young (Reach/D365). > Work closely with portfolio architect Dennis Kiesel and various ICS engineers supporting Azure and AI services. > Hold weekly team meetings and 1:1s with each manager to maintain alignment and support individual well-being, performance, and growth. > Weekly development and development QA with managers. > Meet with ICS contacts specifically related to AI initiatives. These meetings ensure compliance with security protocols and help secure the support needed to advance our work. | G9: High engagement and alignment with stakeholders and team Strong cross-team collaboration with IT and ICS partners Timely delivery of AI-related initiatives Effective QA and development with managers | H9: 90% or better of projects delivered on time and within scope across our team (Overall execution and alignment with org priorities) 85% or better stakeholder satisfaction score (Effectiveness of collaboration and communication at an operational level) 80% or better engagement score from quarterly team surveys or retention metrics (Leadership quality and team stability) One or more of our AI initiatives successfully integrated into business processes per quarter (Strategic contribution to modernization and innovation) | I9: None | J9: None | K9: Quarterly & Biannually
A10: Dezjaron Dorsey | B10: AI Manager | C10: Digital Ops | D10: Complete | E10: > Track project progression > Manage team through 1on1s and team meetings > Source solutions to unfolding project challenges > Build AI/ML Architecture > Build data model > Weekly reporting meetings > Maintain and manage >> Azure Developers board >> GitHub Repos >> Azure DevOps Pipelines | F10: Course Assistant Fluency Assistant Companion Assistant (different from Native) Grader Assistant Data Model | G10: Ensure Digital Ops final products can be used successfully by the end users. Ensure feedback and improvement backends are built into projects so they can be monitored and maintained. Projects are updated and improved as needed to keep them functioning optimally. | H10: None | I10: None
